<robot name="dyros_jet">
  <link name="Pelvis">
    <inertial>
      <origin
        xyz="0.02161 -0.00067 0.00473"
        rpy="0 0 0" />
      <mass
        value="4.465" />
      <inertia
        ixx="0.031924"
        ixy="6.3802E-05"
        ixz="0.00039914"
        iyy="0.0086639"
        iyz="1.6583E-05"
        izz="0.033771" />
    </inertial>
    <visual>
      <origin
        xyz="0 0 0"
        rpy="0 0 0" />
      <geometry>
        <mesh
          filename="package://dyros_jet_description/meshes/Pelvis.STL" />
      </geometry>
      <material
        name="">
        <color
          rgba="0.25098 0.25098 0.25098 1" />
      </material>
    </visual>
    <collision>
      <origin
        xyz="0 0 0"
        rpy="0 0 0" />
      <geometry>
        <mesh
          filename="package://dyros_jet_description/meshes/Pelvis.STL" />
      </geometry>
    </collision>
  </link>
  <link
    name="Waist">
    <inertial>
      <origin
        xyz="0 0 0.0354"
        rpy="0 0 0" />
      <mass
        value="0.182" />
      <inertia
        ixx="0.000652345"
        ixy="8.98273E-11"
        ixz="0"
        iyy="0.000122793"
        iyz="0"
        izz="0.000629724" />
    </inertial>
    <visual>
      <origin
        xyz="0 0 0"
        rpy="0 0 0" />
      <geometry>
        <mesh
          filename="package://dyros_jet_description/meshes/Waist.STL" />
      </geometry>
      <material
        name="">
        <color
          rgba="0.25098 0.25098 0.25098 1" />
      </material>
    </visual>
    <collision>
      <origin
        xyz="0 0 0"
        rpy="0 0 0" />
      <geometry>
        <mesh
          filename="package://dyros_jet_description/meshes/Waist.STL" />
      </geometry>
    </collision>
  </link>
  <joint
    name="WPitch"
    type="revolute">
    <origin
      xyz="0 0 0"
      rpy="0 0 0" />
    <parent
      link="Pelvis" />
    <child
      link="Waist" />
    <limit effort="20" velocity="1.0" lower="-3.14" upper="3.14" />
    <axis
      xyz="0 -1 0" />
  </joint>
  <link
    name="Torso">
    <inertial>
      <origin
        xyz="-0.00771 5E-05 0.23508"
        rpy="0 0 0" />
      <mass
        value="10.25" />
      <inertia
        ixx="0.153979425"
        ixy="5.26017E-05"
        ixz="0.002566229"
        iyy="0.087379402"
        iyz="6.74756E-05"
        izz="0.12505596" />
    </inertial>
    <visual>
      <origin
        xyz="0 0 0"
        rpy="0 0 0" />
      <geometry>
        <mesh
          filename="package://dyros_jet_description/meshes/Torso.STL" />
      </geometry>
      <material
        name="">
        <color
          rgba="0.25098 0.25098 0.25098 1" />
      </material>
    </visual>
    <collision>
      <origin
        xyz="0 0 0"
        rpy="0 0 0" />
      <geometry>
        <mesh
          filename="package://dyros_jet_description/meshes/Torso.STL" />
      </geometry>
    </collision>
  </link>
  <joint
    name="WYaw"
    type="revolute">
    <origin
      xyz="0 0 0"
      rpy="0 0 0" />
    <parent
      link="Waist" />
    <child
      link="Torso" />
    <axis
      xyz="0 0 -1" />
    <limit effort="20" velocity="1.0" lower="-3.14" upper="3.14" />
  </joint>
  <link
    name="HeadYaw">
    <inertial>
      <origin
        xyz="-6.93889390390723E-18 0.0107310663516784 -0.00097841407512067"
        rpy="0 0 0" />
      <mass
        value="0.158333778337574" />
      <inertia
        ixx="0.000122092021067417"
        ixy="-1.60047662314617E-20"
        ixz="-4.68562156789905E-21"
        iyy="4.93071898866527E-05"
        iyz="1.66241384588246E-06"
        izz="0.000120595722236805" />
    </inertial>
    <visual>
      <origin
        xyz="0 0 0"
        rpy="0 0 0" />
      <geometry>
        <mesh
          filename="package://dyros_jet_description/meshes/HeadYaw.STL" />
      </geometry>
      <material
        name="">
        <color
          rgba="0.250980392156863 0.250980392156863 0.250980392156863 1" />
      </material>
    </visual>
    <collision>
      <origin
        xyz="0 0 0"
        rpy="0 0 0" />
      <geometry>
        <mesh
          filename="package://dyros_jet_description/meshes/HeadYaw.STL" />
      </geometry>
    </collision>
  </link>
  <joint
    name="HYaw"
    type="revolute">
    <origin
      xyz="0.00024999999999991 0 0.3955"
      rpy="-1.46724575673604E-16 8.13272469776318E-17 -5.55111512312578E-17" />
    <parent
      link="Torso" />
    <child
      link="HeadYaw" />
    <axis
      xyz="0 0 1" />
    <limit effort="20" velocity="1.0" lower="-3.14" upper="3.14" />
  </joint>
  <link
    name="HeadPitch">
    <inertial>
      <origin
        xyz="-3.29597460435593E-16 0.0112583399578345 0.0635601103937095"
        rpy="0 0 0" />
      <mass
        value="0.299825355067824" />
      <inertia
        ixx="0.000331516491838581"
        ixy="1.4106091681348E-18"
        ixz="6.59672457404599E-18"
        iyy="0.000272084210955041"
        iyz="1.264842383911E-05"
        izz="0.000206117858224055" />
    </inertial>
    <visual>
      <origin
        xyz="0 0 0"
        rpy="0 0 0" />
      <geometry>
        <mesh
          filename="package://dyros_jet_description/meshes/HeadPitch.STL" />
      </geometry>
      <material
        name="">
        <color
          rgba="0.792156862745098 0.819607843137255 0.933333333333333 1" />
      </material>
    </visual>
    <collision>
      <origin
        xyz="0 0 0"
        rpy="0 0 0" />
      <geometry>
        <mesh
          filename="package://dyros_jet_description/meshes/HeadPitch.STL" />
      </geometry>
    </collision>
  </link>
  <joint
    name="HPitch"
    type="revolute">
    <origin
      xyz="0 0 0"
      rpy="-8.09996223546451E-49 0 0" />
    <parent
      link="HeadYaw" />
    <child
      link="HeadPitch" />
    <axis
      xyz="0 -1 0" />
    <limit effort="20" velocity="1.0" lower="-3.14" upper="3.14" />
  </joint>
  <link
    name="ChestLidar">
    <inertial>
      <origin
        xyz="-0.00489419809964197 -0.0162697827065506 -0.0277015457355138"
        rpy="0 0 0" />
      <mass
        value="0.213148156323205" />
      <inertia
        ixx="0.000164331768340605"
        ixy="3.23960123346954E-08"
        ixz="4.45817273768886E-07"
        iyy="9.90191365035351E-05"
        iyz="-7.95345089033756E-07"
        izz="0.000143755032610095" />
    </inertial>
    <visual>
      <origin
        xyz="0 0 0"
        rpy="0 0 0" />
      <geometry>
        <mesh
          filename="package://dyros_jet_description/meshes/ChestLidar.STL" />
      </geometry>
      <material
        name="">
        <color
          rgba="0.250980392156863 0.250980392156863 0.250980392156863 1" />
      </material>
    </visual>
    <collision>
      <origin
        xyz="0 0 0"
        rpy="0 0 0" />
      <geometry>
        <mesh
          filename="package://dyros_jet_description/meshes/ChestLidar.STL" />
      </geometry>
    </collision>
  </link>
  <joint
    name="CLidar"
    type="revolute">
    <origin
      xyz="0.0497499999999999 0 0.279"
      rpy="1.13977792342471E-17 -6.3992017133219E-18 2.77555756156289E-16" />
    <parent
      link="Torso" />
    <child
      link="ChestLidar" />
    <axis
      xyz="0 0 1" />
    <limit effort="20" velocity="1.0" lower="-3.14" upper="3.14" />
  </joint>
  <link
    name="R_ShoulderPitch">
    <inertial>
      <origin
        xyz="-0.00107 0.00115 -0.00158"
        rpy="0 0 0" />
      <mass
        value="1.04" />
      <inertia
        ixx="0.00083442"
        ixy="2.5439E-06"
        ixz="5.4563E-05"
        iyy="0.0020512"
        iyz="8.7696E-06"
        izz="0.0017489" />
    </inertial>
    <visual>
      <origin
        xyz="0 0 0"
        rpy="0 0 0" />
      <geometry>
        <mesh
          filename="package://dyros_jet_description/meshes/R_ShoulderPitch.STL" />
      </geometry>
      <material
        name="">
        <color
          rgba="0.25098 0.25098 0.25098 1" />
      </material>
    </visual>
    <collision>
      <origin
        xyz="0 0 0"
        rpy="0 0 0" />
      <geometry>
        <mesh
          filename="package://dyros_jet_description/meshes/R_ShoulderPitch.STL" />
      </geometry>
    </collision>
  </link>
  <joint
    name="RArm1"
    type="revolute">
    <origin
      xyz="0 -0.210000000000001 0.2785"
      rpy="5.55111512312635E-17 -8.16935492224716E-17 3.40859647465655E-15" />
    <parent
      link="Torso" />
    <child
      link="R_ShoulderPitch" />
    <axis
      xyz="0 -1 0" />
    <limit effort="20" velocity="1.0" lower="-3.14" upper="3.14" />
  </joint>
  <link
    name="R_ShoulderRoll">
    <inertial>
      <origin
        xyz="0.00491 0 -0.03719"
        rpy="0 0 0" />
      <mass
        value="0.136" />
      <inertia
        ixx="8.6768E-05"
        ixy="0"
        ixz="1.2056E-05"
        iyy="0.00045048"
        iyz="0"
        izz="0.000447508" />
    </inertial>
    <visual>
      <origin
        xyz="0 0 0"
        rpy="0 0 0" />
      <geometry>
        <mesh
          filename="package://dyros_jet_description/meshes/R_ShoulderRoll.STL" />
      </geometry>
      <material
        name="">
        <color
          rgba="0.25098 0.25098 0.25098 1" />
      </material>
    </visual>
    <collision>
      <origin
        xyz="0 0 0"
        rpy="0 0 0" />
      <geometry>
        <mesh
          filename="package://dyros_jet_description/meshes/R_ShoulderRoll.STL" />
      </geometry>
    </collision>
  </link>
  <joint
    name="RArm2"
    type="revolute">
    <origin
      xyz="0 0 0"
      rpy="-5.01640966397328E-34 0 0" />
    <parent
      link="R_ShoulderPitch" />
    <child
      link="R_ShoulderRoll" />
    <axis
      xyz="1 0 0" />
    <limit effort="20" velocity="1.0" lower="-3.14" upper="3.14" />
  </joint>
  <link
    name="R_Brachium">
    <inertial>
      <origin
        xyz="-0.00077 0.01218 -0.18284"
        rpy="0 0 0" />
      <mass
        value="2.021" />
      <inertia
        ixx="0.013403"
        ixy="-2.8167E-05"
        ixz="0.00012794"
        iyy="0.013651"
        iyz="-0.0019881"
        izz="0.0022421" />
    </inertial>
    <visual>
      <origin
        xyz="0 0 0"
        rpy="0 0 0" />
      <geometry>
        <mesh
          filename="package://dyros_jet_description/meshes/R_Brachium.STL" />
      </geometry>
      <material
        name="">
        <color
          rgba="0.25098 0.25098 0.25098 1" />
      </material>
    </visual>
    <collision>
      <origin
        xyz="0 0 0"
        rpy="0 0 0" />
      <geometry>
        <mesh
          filename="package://dyros_jet_description/meshes/R_Brachium.STL" />
      </geometry>
    </collision>
  </link>
  <joint
    name="RArm3"
    type="revolute">
    <origin
      xyz="0 0 0"
      rpy="-5.01640966397328E-34 0 0" />
    <parent
      link="R_ShoulderRoll" />
    <child
      link="R_Brachium" />
    <axis
      xyz="0 0 -1" />
    <limit effort="20" velocity="1.0" lower="-3.14" upper="3.14" />
  </joint>
  <link
    name="R_ForeArm">
    <inertial>
      <origin
        xyz="0.00054 -0.02977 -0.11898"
        rpy="0 0 0" />
      <mass
        value="1.161" />
      <inertia
        ixx="0.0046865"
        ixy="1.1681E-05"
        ixz="6.8122E-05"
        iyy="0.0051786"
        iyz="7.37E-05"
        izz="0.001372" />
    </inertial>
    <visual>
      <origin
        xyz="0 0 0"
        rpy="0 0 0" />
      <geometry>
        <mesh
          filename="package://dyros_jet_description/meshes/R_ForeArm.STL" />
      </geometry>
      <material
        name="">
        <color
          rgba="0.25098 0.25098 0.25098 1" />
      </material>
    </visual>
    <collision>
      <origin
        xyz="0 0 0"
        rpy="0 0 0" />
      <geometry>
        <mesh
          filename="package://dyros_jet_description/meshes/R_ForeArm.STL" />
      </geometry>
    </collision>
  </link>
  <joint
    name="RArm4"
    type="revolute">
    <origin
      xyz="0 0.02995 -0.264"
      rpy="-2.22044604925033E-16 3.94430452610506E-31 -8.15575010455706E-17" />
    <parent
      link="R_Brachium" />
    <child
      link="R_ForeArm" />
    <axis
      xyz="1 0 0" />
    <limit effort="20" velocity="1.0" lower="-3.14" upper="3.14" />
  </joint>
  <link
    name="R_WristRoll">
    <inertial>
      <origin
        xyz="-0.00252 0 0.0018"
        rpy="0 0 0" />
      <mass
        value="0.37" />
      <inertia
        ixx="0.00011874"
        ixy="2.0977E-10"
        ixz="1.6788E-06"
        iyy="0.00027329"
        iyz="9.9892E-12"
        izz="0.000267" />
    </inertial>
    <visual>
      <origin
        xyz="0 0 0"
        rpy="0 0 0" />
      <geometry>
        <mesh
          filename="package://dyros_jet_description/meshes/R_WristRoll.STL" />
      </geometry>
      <material
        name="">
        <color
          rgba="0.25098 0.25098 0.25098 1" />
      </material>
    </visual>
    <collision>
      <origin
        xyz="0 0 0"
        rpy="0 0 0" />
      <geometry>
        <mesh
          filename="package://dyros_jet_description/meshes/R_WristRoll.STL" />
      </geometry>
    </collision>
  </link>
  <joint
    name="RArm5"
    type="revolute">
    <origin
      xyz="0 -0.0300000000000077 -0.252"
      rpy="-4.55191440096314E-15 0 1.07801232877069E-17" />
    <parent
      link="R_ForeArm" />
    <child
      link="R_WristRoll" />
    <axis
      xyz="0 0 -1" />
    <limit effort="20" velocity="1.0" lower="-3.14" upper="3.14" />
  </joint>
  <link
    name="R_WristPitch">
    <inertial>
      <origin
        xyz="0.00346 0 -0.02673"
        rpy="0 0 0" />
      <mass
        value="0.102" />
      <inertia
        ixx="3.8333E-05"
        ixy="0"
        ixz="5.3967E-06"
        iyy="0.0001563"
        iyz="0"
        izz="0.00015475" />
    </inertial>
    <visual>
      <origin
        xyz="0 0 0"
        rpy="0 0 0" />
      <geometry>
        <mesh
          filename="package://dyros_jet_description/meshes/R_WristPitch.STL" />
      </geometry>
      <material
        name="">
        <color
          rgba="0.25098 0.25098 0.25098 1" />
      </material>
    </visual>
    <collision>
      <origin
        xyz="0 0 0"
        rpy="0 0 0" />
      <geometry>
        <mesh
          filename="package://dyros_jet_description/meshes/R_WristPitch.STL" />
      </geometry>
    </collision>
  </link>
  <joint
    name="RArm6"
    type="revolute">
    <origin
      xyz="0 0 0"
      rpy="2.77213191653758E-31 0 0" />
    <parent
      link="R_WristRoll" />
    <child
      link="R_WristPitch" />
    <axis
      xyz="1 0 0" />
    <limit effort="20" velocity="1.0" lower="-3.14" upper="3.14" />
  </joint>
  <link
    name="R_WristYaw">
    <inertial>
      <origin
        xyz="-2E-05 -0.00075 -0.19179"
        rpy="0 0 0" />
      <mass
        value="1.44" />
      <inertia
        ixx="0.010215"
        ixy="9.4269E-06"
        ixz="4.1417E-06"
        iyy="0.010186"
        iyz="-0.00010973"
        izz="0.0012227" />
    </inertial>
    <visual>
      <origin
        xyz="0 0 0"
        rpy="0 0 0" />
      <geometry>
        <mesh
          filename="package://dyros_jet_description/meshes/R_WristYaw.STL" />
      </geometry>
      <material
        name="">
        <color
          rgba="0.25098 0.25098 0.25098 1" />
      </material>
    </visual>
    <collision>
      <origin
        xyz="0 0 0"
        rpy="0 0 0" />
      <geometry>
        <mesh
          filename="package://dyros_jet_description/meshes/R_WristYaw.STL" />
      </geometry>
    </collision>
  </link>
  <joint
    name="RArm7"
    type="revolute">
    <origin
      xyz="0 0 0"
      rpy="2.77213191653758E-31 0 0" />
    <parent
      link="R_WristPitch" />
    <child
      link="R_WristYaw" />
    <axis
      xyz="0 0 -1" />
    <limit effort="20" velocity="1.0" lower="-3.14" upper="3.14" />
  </joint>
  <link
    name="L_ShoulderPitch">
    <inertial>
      <origin
        xyz="-0.00107 -0.00115 -0.00158"
        rpy="0 0 0" />
      <mass
        value="1.04" />
      <inertia
        ixx="0.00083442"
        ixy="-2.5439E-06"
        ixz="5.4563E-05"
        iyy="0.0020512"
        iyz="-8.7696E-06"
        izz="0.001748906" />
    </inertial>
    <visual>
      <origin
        xyz="0 0 0"
        rpy="0 0 0" />
      <geometry>
        <mesh
          filename="package://dyros_jet_description/meshes/L_ShoulderPitch.STL" />
      </geometry>
      <material
        name="">
        <color
          rgba="0.25098 0.25098 0.25098 1" />
      </material>
    </visual>
    <collision>
      <origin
        xyz="0 0 0"
        rpy="0 0 0" />
      <geometry>
        <mesh
          filename="package://dyros_jet_description/meshes/L_ShoulderPitch.STL" />
      </geometry>
    </collision>
  </link>
  <joint
    name="LArm1"
    type="revolute">
    <origin
      xyz="0 0.21 0.278499999999999"
      rpy="-3.50297629579337E-15 -3.3823993732778E-17 -2.87254826580342E-17" />
    <parent
      link="Torso" />
    <child
      link="L_ShoulderPitch" />
    <axis
      xyz="0 1 0" />
    <limit effort="20" velocity="1.0" lower="-3.14" upper="3.14" />
  </joint>
  <link
    name="L_ShoulderRoll">
    <inertial>
      <origin
        xyz="0.00491 0 -0.03719"
        rpy="0 0 0" />
      <mass
        value="0.136" />
      <inertia
        ixx="8.6768E-05"
        ixy="0"
        ixz="1.2056E-05"
        iyy="0.00045048"
        iyz="0"
        izz="0.000447508" />
    </inertial>
    <visual>
      <origin
        xyz="0 0 0"
        rpy="0 0 0" />
      <geometry>
        <mesh
          filename="package://dyros_jet_description/meshes/L_ShoulderRoll.STL" />
      </geometry>
      <material
        name="">
        <color
          rgba="0.79216 0.81961 0.93333 1" />
      </material>
    </visual>
    <collision>
      <origin
        xyz="0 0 0"
        rpy="0 0 0" />
      <geometry>
        <mesh
          filename="package://dyros_jet_description/meshes/L_ShoulderRoll.STL" />
      </geometry>
    </collision>
  </link>
  <joint
    name="LArm2"
    type="revolute">
    <origin
      xyz="0 0 0"
      rpy="9.05998285948983E-34 0 0" />
    <parent
      link="L_ShoulderPitch" />
    <child
      link="L_ShoulderRoll" />
    <axis
      xyz="1 0 0" />
    <limit effort="20" velocity="1.0" lower="-3.14" upper="3.14" />
  </joint>
  <link
    name="L_Brachium">
    <inertial>
      <origin
        xyz="-0.00077 -0.01218 -0.18284"
        rpy="0 0 0" />
      <mass
        value="2.021" />
      <inertia
        ixx="0.013403"
        ixy="2.8167E-05"
        ixz="0.00012794"
        iyy="0.013651"
        iyz="0.0019881"
        izz="0.0022421" />
    </inertial>
    <visual>
      <origin
        xyz="0 0 0"
        rpy="0 0 0" />
      <geometry>
        <mesh
          filename="package://dyros_jet_description/meshes/L_Brachium.STL" />
      </geometry>
      <material
        name="">
        <color
          rgba="0.25098 0.25098 0.25098 1" />
      </material>
    </visual>
    <collision>
      <origin
        xyz="0 0 0"
        rpy="0 0 0" />
      <geometry>
        <mesh
          filename="package://dyros_jet_description/meshes/L_Brachium.STL" />
      </geometry>
    </collision>
  </link>
  <joint
    name="LArm3"
    type="revolute">
    <origin
      xyz="0 0 0"
      rpy="9.05998285948983E-34 0 0" />
    <parent
      link="L_ShoulderRoll" />
    <child
      link="L_Brachium" />
    <axis
      xyz="0 0 -1" />
    <limit effort="20" velocity="1.0" lower="-3.14" upper="3.14" />
  </joint>
  <link
    name="L_ForeArm">
    <inertial>
      <origin
        xyz="0.00054 0.02977 -0.11898"
        rpy="0 0 0" />
      <mass
        value="1.161" />
      <inertia
        ixx="0.0046865"
        ixy="-1.1681E-05"
        ixz="6.8122E-05"
        iyy="0.0051786"
        iyz="-7.37E-05"
        izz="0.001372" />
    </inertial>
    <visual>
      <origin
        xyz="0 0 0"
        rpy="0 0 0" />
      <geometry>
        <mesh
          filename="package://dyros_jet_description/meshes/L_ForeArm.STL" />
      </geometry>
      <material
        name="">
        <color
          rgba="0.25098 0.25098 0.25098 1" />
      </material>
    </visual>
    <collision>
      <origin
        xyz="0 0 0"
        rpy="0 0 0" />
      <geometry>
        <mesh
          filename="package://dyros_jet_description/meshes/L_ForeArm.STL" />
      </geometry>
    </collision>
  </link>
  <joint
    name="LArm4"
    type="revolute">
    <origin
      xyz="0 -0.0299499999999996 -0.264"
      rpy="-6.60365316668195E-15 -4.32978028030698E-17 -4.41113391154086E-11" />
    <parent
      link="L_Brachium" />
    <child
      link="L_ForeArm" />
    <axis
      xyz="1 0 0" />
    <limit effort="20" velocity="1.0" lower="-3.14" upper="3.14" />
  </joint>
  <link
    name="L_WristRoll">
    <inertial>
      <origin
        xyz="-0.00252 0 0.0018"
        rpy="0 0 0" />
      <mass
        value="0.37" />
      <inertia
        ixx="0.00011874"
        ixy="-2.0977E-10"
        ixz="1.6788E-06"
        iyy="0.00027329"
        iyz="-9.9892E-12"
        izz="0.000267" />
    </inertial>
    <visual>
      <origin
        xyz="0 0 0"
        rpy="0 0 0" />
      <geometry>
        <mesh
          filename="package://dyros_jet_description/meshes/L_WristRoll.STL" />
      </geometry>
      <material
        name="">
        <color
          rgba="0.25098 0.25098 0.25098 1" />
      </material>
    </visual>
    <collision>
      <origin
        xyz="0 0 0"
        rpy="0 0 0" />
      <geometry>
        <mesh
          filename="package://dyros_jet_description/meshes/L_WristRoll.STL" />
      </geometry>
    </collision>
  </link>
  <joint
    name="LArm5"
    type="revolute">
    <origin
      xyz="0 0.0300000000000082 -0.252"
      rpy="1.14111415164118E-14 -3.01474756672852E-25 4.41079816606662E-11" />
    <parent
      link="L_ForeArm" />
    <child
      link="L_WristRoll" />
    <axis
      xyz="0 0 1" />
    <limit effort="20" velocity="1.0" lower="-3.14" upper="3.14" />
  </joint>
  <link
    name="L_WristPitch">
    <inertial>
      <origin
        xyz="0.00346 0 -0.02673"
        rpy="0 0 0" />
      <mass
        value="0.102" />
      <inertia
        ixx="3.8333E-05"
        ixy="0"
        ixz="5.3967E-06"
        iyy="0.0001563"
        iyz="0"
        izz="0.00015475" />
    </inertial>
    <visual>
      <origin
        xyz="0 0 0"
        rpy="0 0 0" />
      <geometry>
        <mesh
          filename="package://dyros_jet_description/meshes/L_WristPitch.STL" />
      </geometry>
      <material
        name="">
        <color
          rgba="0.79216 0.81961 0.93333 1" />
      </material>
    </visual>
    <collision>
      <origin
        xyz="0 0 0"
        rpy="0 0 0" />
      <geometry>
        <mesh
          filename="package://dyros_jet_description/meshes/L_WristPitch.STL" />
      </geometry>
    </collision>
  </link>
  <joint
    name="LArm6"
    type="revolute">
    <origin
      xyz="0 0 0"
      rpy="-5.96519563727706E-32 0 0" />
    <parent
      link="L_WristRoll" />
    <child
      link="L_WristPitch" />
    <axis
      xyz="-1 0 0" />
    <limit effort="20" velocity="1.0" lower="-3.14" upper="3.14" />
  </joint>
  <link
    name="L_WristYaw">
    <inertial>
      <origin
        xyz="-2E-05 0.00075 -0.19179"
        rpy="0 0 0" />
      <mass
        value="1.44" />
      <inertia
        ixx="0.010215"
        ixy="-9.4269E-06"
        ixz="4.1417E-06"
        iyy="0.010186"
        iyz="0.00010973"
        izz="0.0012227" />
    </inertial>
    <visual>
      <origin
        xyz="0 0 0"
        rpy="0 0 0" />
      <geometry>
        <mesh
          filename="package://dyros_jet_description/meshes/L_WristYaw.STL" />
      </geometry>
      <material
        name="">
        <color
          rgba="0.79216 0.81961 0.93333 1" />
      </material>
    </visual>
    <collision>
      <origin
        xyz="0 0 0"
        rpy="0 0 0" />
      <geometry>
        <mesh
          filename="package://dyros_jet_description/meshes/L_WristYaw.STL" />
      </geometry>
    </collision>
  </link>
  <joint
    name="LArm7"
    type="revolute">
    <origin
      xyz="0 0 0"
      rpy="-5.96519563727706E-32 0 0" />
    <parent
      link="L_WristPitch" />
    <child
      link="L_WristYaw" />
    <axis
      xyz="0 0 1" />
    <limit effort="20" velocity="1.0" lower="-3.14" upper="3.14" />
  </joint>
  <link
    name="R_HipYaw">
    <inertial>
      <origin
        xyz="-0.03615 0 0.06372"
        rpy="0 0 0" />
      <mass
        value="1.455" />
      <inertia
        ixx="0.0033909"
        ixy="-1.5937E-07"
        ixz="0.00079273"
        iyy="0.005794"
        iyz="1.271E-07"
        izz="0.0031352" />
    </inertial>
    <visual>
      <origin
        xyz="0 0 0"
        rpy="0 0 0" />
      <geometry>
        <mesh
          filename="package://dyros_jet_description/meshes/R_HipYaw.STL" />
      </geometry>
      <material
        name="">
        <color
          rgba="0.25098 0.25098 0.25098 1" />
      </material>
    </visual>
    <collision>
      <origin
        xyz="0 0 0"
        rpy="0 0 0" />
      <geometry>
        <mesh
          filename="package://dyros_jet_description/meshes/R_HipYaw.STL" />
      </geometry>
    </collision>
  </link>
  <joint
    name="RLeg1"
    type="revolute">
    <origin
      xyz="0 -0.104999999999998 -0.182900000000001"
      rpy="0 0 -5.55111512312578E-17" />
    <parent
      link="Pelvis" />
    <child
      link="R_HipYaw" />
    <axis
      xyz="0 0 1" />
    <limit effort="20" velocity="1.0" lower="-3.14" upper="3.14" />
  </joint>
  <link
    name="R_HipRoll">
    <inertial>
      <origin
        xyz="0 0.01192 0"
        rpy="0 0 0" />
      <mass
        value="1.022" />
      <inertia
        ixx="0.001709"
        ixy="0"
        ixz="0"
        iyy="0.00058314"
        iyz="7.2567E-09"
        izz="0.0016687" />
    </inertial>
    <visual>
      <origin
        xyz="0 0 0"
        rpy="0 0 0" />
      <geometry>
        <mesh
          filename="package://dyros_jet_description/meshes/R_HipRoll.STL" />
      </geometry>
      <material
        name="">
        <color
          rgba="0.25098 0.25098 0.25098 1" />
      </material>
    </visual>
    <collision>
      <origin
        xyz="0 0 0"
        rpy="0 0 0" />
      <geometry>
        <mesh
          filename="package://dyros_jet_description/meshes/R_HipRoll.STL" />
      </geometry>
    </collision>
  </link>
  <joint
    name="RLeg2"
    type="revolute">
    <origin
      xyz="0 0 0"
      rpy="0 0 0" />
    <parent
      link="R_HipYaw" />
    <child
      link="R_HipRoll" />
    <axis
      xyz="-1 0 0" />
    <limit effort="20" velocity="1.0" lower="-3.14" upper="3.14" />
  </joint>
  <link
    name="R_Thigh">
    <inertial>
      <origin
        xyz="0.01216 0.02093 -0.15218"
        rpy="0 0 0" />
      <mass
        value="3.394" />
      <inertia
        ixx="0.016667"
        ixy="3.0626E-06"
        ixz="-1.1364E-05"
        iyy="0.01192"
        iyz="-1.3286E-05"
        izz="0.0072258" />
    </inertial>
    <visual>
      <origin
        xyz="0 0 0"
        rpy="0 0 0" />
      <geometry>
        <mesh
          filename="package://dyros_jet_description/meshes/R_Thigh.STL" />
      </geometry>
      <material
        name="">
        <color
          rgba="0.25098 0.25098 0.25098 1" />
      </material>
    </visual>
    <collision>
      <origin
        xyz="0 0 0"
        rpy="0 0 0" />
      <geometry>
        <mesh
          filename="package://dyros_jet_description/meshes/R_Thigh.STL" />
      </geometry>
    </collision>
  </link>
  <joint
    name="RLeg3"
    type="revolute">
    <origin
      xyz="0 0 0"
      rpy="0 0 0" />
    <parent
      link="R_HipRoll" />
    <child
      link="R_Thigh" />
    <axis
      xyz="0 1 0" />
    <limit effort="20" velocity="1.0" lower="-3.14" upper="3.14" />
  </joint>
  <link
    name="R_Shin">
    <inertial>
      <origin
        xyz="0.00716 0.02052 -0.11371"
        rpy="0 0 0" />
      <mass
        value="4.745" />
      <inertia
        ixx="0.054279"
        ixy="-0.00019489"
        ixz="0.001528"
        iyy="0.048711"
        iyz="-0.0039209"
        izz="0.011166" />
    </inertial>
    <visual>
      <origin
        xyz="0 0 0"
        rpy="0 0 0" />
      <geometry>
        <mesh
          filename="package://dyros_jet_description/meshes/R_Shin.STL" />
      </geometry>
      <material
        name="">
        <color
          rgba="0.25098 0.25098 0.25098 1" />
      </material>
    </visual>
    <collision>
      <origin
        xyz="0 0 0"
        rpy="0 0 0" />
      <geometry>
        <mesh
          filename="package://dyros_jet_description/meshes/R_Shin.STL" />
      </geometry>
    </collision>
  </link>
  <joint
    name="RLeg4"
    type="revolute">
    <origin
      xyz="-0.00599999999999734 0 -0.299999999999999"
      rpy="3.80913305828281E-16 -3.44169137633798E-15 -3.29868778489808E-15" />
    <parent
      link="R_Thigh" />
    <child
      link="R_Shin" />
    <axis
      xyz="0 -1 0" />
    <limit effort="20" velocity="1.0" lower="-3.14" upper="3.14" />
  </joint>
  <link
    name="R_AnkleRoll">
    <inertial>
      <origin
        xyz="-0.03892 -0.0269 -0.027"
        rpy="0 0 0" />
      <mass
        value="1.022" />
      <inertia
        ixx="0.00058314"
        ixy="-7.2567E-09"
        ixz="0"
        iyy="0.0016687"
        iyz="0"
        izz="0.001709" />
    </inertial>
    <visual>
      <origin
        xyz="0 0 0"
        rpy="0 0 0" />
      <geometry>
        <mesh
          filename="package://dyros_jet_description/meshes/R_AnkleRoll.STL" />
      </geometry>
      <material
        name="">
        <color
          rgba="0.25098 0.25098 0.25098 1" />
      </material>
    </visual>
    <collision>
      <origin
        xyz="0 0 0"
        rpy="0 0 0" />
      <geometry>
        <mesh
          filename="package://dyros_jet_description/meshes/R_AnkleRoll.STL" />
      </geometry>
    </collision>
  </link>
  <joint
    name="RLeg5"
    type="revolute">
    <origin
      xyz="0 0 -0.300000000000001"
      rpy="-3.38968639707624E-15 1.11022302462516E-16 3.12743027860508E-16" />
    <parent
      link="R_Shin" />
    <child
      link="R_AnkleRoll" />
    <axis
      xyz="0 1 0" />
    <limit effort="20" velocity="1.0" lower="-3.14" upper="3.14" />
  </joint>
  <link
    name="R_Foot">
    <inertial>
      <origin
        xyz="-0.00321 2E-05 -0.07997"
        rpy="0 0 0" />
      <mass
        value="1.32" />
      <inertia
        ixx="0.002529"
        ixy="-8.5403E-08"
        ixz="-0.00015402"
        iyy="0.0058499"
        iyz="-4.2557E-07"
        izz="0.0071735" />
    </inertial>
    <visual>
      <origin
        xyz="0 0 0"
        rpy="0 0 0" />
      <geometry>
        <mesh
          filename="package://dyros_jet_description/meshes/R_Foot.STL" />
      </geometry>
      <material
        name="">
        <color
          rgba="0.25098 0.25098 0.25098 1" />
      </material>
    </visual>
    <collision>
      <origin
        xyz="0 0 0"
        rpy="0 0 0" />
      <geometry>
        <mesh
          filename="package://dyros_jet_description/meshes/R_Foot.STL" />
      </geometry>
    </collision>
  </link>
  <joint
    name="RLeg6"
    type="revolute">
    <origin
      xyz="0 0 0"
      rpy="-8.44325433030121E-32 0 0" />
    <parent
      link="R_AnkleRoll" />
    <child
      link="R_Foot" />
    <axis
      xyz="-1 0 0" />
    <limit effort="20" velocity="1.0" lower="-3.14" upper="3.14" />
  </joint>
  <link
    name="L_HipYaw">
    <inertial>
      <origin
        xyz="-0.03615 0 0.06372"
        rpy="0 0 0" />
      <mass
        value="1.455" />
      <inertia
        ixx="0.0033909"
        ixy="1.5937E-07"
        ixz="0.00079273"
        iyy="0.005794"
        iyz="-1.271E-07"
        izz="0.0031352" />
    </inertial>
    <visual>
      <origin
        xyz="0 0 0"
        rpy="0 0 0" />
      <geometry>
        <mesh
          filename="package://dyros_jet_description/meshes/L_HipYaw.STL" />
      </geometry>
      <material
        name="">
        <color
          rgba="0.25098 0.25098 0.25098 1" />
      </material>
    </visual>
    <collision>
      <origin
        xyz="0 0 0"
        rpy="0 0 0" />
      <geometry>
        <mesh
          filename="package://dyros_jet_description/meshes/L_HipYaw.STL" />
      </geometry>
    </collision>
  </link>
  <joint
    name="LLeg1"
    type="revolute">
    <origin
      xyz="0 0.104999999999992 -0.1829"
      rpy="-2.30152571752523E-18 2.59052361780078E-17 -2.77555756156289E-17" />
    <parent
      link="Pelvis" />
    <child
      link="L_HipYaw" />
    <axis
      xyz="0 0 1" />
    <limit effort="20" velocity="1.0" lower="-3.14" upper="3.14" />
  </joint>
  <link
    name="L_HipRoll">
    <inertial>
      <origin
        xyz="0 -0.01192 0"
        rpy="0 0 0" />
      <mass
        value="1.022" />
      <inertia
        ixx="0.001709"
        ixy="0"
        ixz="0"
        iyy="0.00058314"
        iyz="-7.2567E-09"
        izz="0.0016687" />
    </inertial>
    <visual>
      <origin
        xyz="0 0 0"
        rpy="0 0 0" />
      <geometry>
        <mesh
          filename="package://dyros_jet_description/meshes/L_HipRoll.STL" />
      </geometry>
      <material
        name="">
        <color
          rgba="0.25098 0.25098 0.25098 1" />
      </material>
    </visual>
    <collision>
      <origin
        xyz="0 0 0"
        rpy="0 0 0" />
      <geometry>
        <mesh
          filename="package://dyros_jet_description/meshes/L_HipRoll.STL" />
      </geometry>
    </collision>
  </link>
  <joint
    name="LLeg2"
    type="revolute">
    <origin
      xyz="0 0 0"
      rpy="5.13572361754725E-35 0 0" />
    <parent
      link="L_HipYaw" />
    <child
      link="L_HipRoll" />
    <axis
      xyz="-1 0 0" />
    <limit effort="20" velocity="1.0" lower="-3.14" upper="3.14" />
  </joint>
  <link
    name="L_Thigh">
    <inertial>
      <origin
        xyz="0.01216 -0.02093 -0.15218"
        rpy="0 0 0" />
      <mass
        value="3.394" />
      <inertia
        ixx="0.016667"
        ixy="-3.0626E-06"
        ixz="-1.1364E-05"
        iyy="0.01192"
        iyz="1.3286E-05"
        izz="0.0072258" />
    </inertial>
    <visual>
      <origin
        xyz="0 0 0"
        rpy="0 0 0" />
      <geometry>
        <mesh
          filename="package://dyros_jet_description/meshes/L_Thigh.STL" />
      </geometry>
      <material
        name="">
        <color
          rgba="0.79216 0.81961 0.93333 1" />
      </material>
    </visual>
    <collision>
      <origin
        xyz="0 0 0"
        rpy="0 0 0" />
      <geometry>
        <mesh
          filename="package://dyros_jet_description/meshes/L_Thigh.STL" />
      </geometry>
    </collision>
  </link>
  <joint
    name="LLeg3"
    type="revolute">
    <origin
      xyz="0 0 0"
      rpy="5.13572361754725E-35 0 0" />
    <parent
      link="L_HipRoll" />
    <child
      link="L_Thigh" />
    <axis
      xyz="0 -1 0" />
    <limit effort="20" velocity="1.0" lower="-3.14" upper="3.14" />
  </joint>
  <link
    name="L_Shin">
    <inertial>
      <origin
        xyz="0.00716 -0.02052 -0.11371"
        rpy="0 0 0" />
      <mass
        value="4.745" />
      <inertia
        ixx="0.054279"
        ixy="0.00019489"
        ixz="0.001528"
        iyy="0.048711"
        iyz="0.0039209"
        izz="0.011166" />
    </inertial>
    <visual>
      <origin
        xyz="0 0 0"
        rpy="0 0 0" />
      <geometry>
        <mesh
          filename="package://dyros_jet_description/meshes/L_Shin.STL" />
      </geometry>
      <material
        name="">
        <color
          rgba="0.25098 0.25098 0.25098 1" />
      </material>
    </visual>
    <collision>
      <origin
        xyz="0 0 0"
        rpy="0 0 0" />
      <geometry>
        <mesh
          filename="package://dyros_jet_description/meshes/L_Shin.STL" />
      </geometry>
    </collision>
  </link>
  <joint
    name="LLeg4"
    type="revolute">
    <origin
      xyz="-0.00599999999999438 0 -0.3"
      rpy="1.93010411399611E-16 4.37220876562746E-15 -3.32152585569689E-16" />
    <parent
      link="L_Thigh" />
    <child
      link="L_Shin" />
    <axis
      xyz="0 1 0" />
    <limit effort="20" velocity="1.0" lower="-3.14" upper="3.14" />
  </joint>
  <link
    name="L_AnkleRoll">
    <inertial>
      <origin
        xyz="-0.03892 0.0269 -0.027"
        rpy="0 0 0" />
      <mass
        value="1.022" />
      <inertia
        ixx="0.00058314"
        ixy="7.2567E-09"
        ixz="0"
        iyy="0.0016687"
        iyz="0"
        izz="0.001709" />
    </inertial>
    <visual>
      <origin
        xyz="0 0 0"
        rpy="0 0 0" />
      <geometry>
        <mesh
          filename="package://dyros_jet_description/meshes/L_AnkleRoll.STL" />
      </geometry>
      <material
        name="">
        <color
          rgba="0.25098 0.25098 0.25098 1" />
      </material>
    </visual>
    <collision>
      <origin
        xyz="0 0 0"
        rpy="0 0 0" />
      <geometry>
        <mesh
          filename="package://dyros_jet_description/meshes/L_AnkleRoll.STL" />
      </geometry>
    </collision>
  </link>
  <joint
    name="LLeg5"
    type="revolute">
    <origin
      xyz="0 0 -0.3"
      rpy="-3.94299247344915E-16 -9.84178201083107E-16 3.28964095806139E-17" />
    <parent
      link="L_Shin" />
    <child
      link="L_AnkleRoll" />
    <axis
      xyz="0 -1 0" />
    <limit effort="20" velocity="1.0" lower="-3.14" upper="3.14" />
  </joint>
  <link
    name="L_Foot">
    <inertial>
      <origin
        xyz="-0.00321 -2E-05 -0.07997"
        rpy="0 0 0" />
      <mass
        value="1.32" />
      <inertia
        ixx="0.002529"
        ixy="8.5403E-08"
        ixz="-0.00015402"
        iyy="0.0058499"
        iyz="4.2557E-07"
        izz="0.0071735" />
    </inertial>
    <visual>
      <origin
        xyz="0 0 0"
        rpy="0 0 0" />
      <geometry>
        <mesh
          filename="package://dyros_jet_description/meshes/L_Foot.STL" />
      </geometry>
      <material
        name="">
        <color
          rgba="0.79216 0.81961 0.93333 1" />
      </material>
    </visual>
    <collision>
      <origin
        xyz="0 0 0"
        rpy="0 0 0" />
      <geometry>
        <mesh
          filename="package://dyros_jet_description/meshes/L_Foot.STL" />
      </geometry>
    </collision>
  </link>
  <joint
    name="LLeg6"
    type="revolute">
    <origin
      xyz="0 0 0"
      rpy="-9.88670541743054E-33 0 0" />
    <parent
      link="L_AnkleRoll" />
    <child
      link="L_Foot" />
    <axis
      xyz="-1 0 0" />
    <limit effort="20" velocity="1.0" lower="-3.14" upper="3.14" />
  </joint>
</robot>
