<robot name="dyros_jet_robot">
  <link name="world"/>
  <joint name="virtual" type="floating">
    <origin xyz="0 0 0" rpy="0 0 0" />
    <parent link="world"/>
    <child link="base_link"/>
    <limit effort="30" velocity="1.0" />
  </joint>

  <link name="base_link">
    <inertial>
      <origin xyz="-0.00106 0 0.049486" rpy="0 0 0" />
      <mass value="1.9994" />
      <inertia
        ixx="0.018401"
        ixy="0"
        ixz="-0.000105"
        iyy="0.008454"
        iyz="0"
        izz="0.011582" />
    </inertial>
    <visual>
      <origin
        xyz="0 0 0"
        rpy="0 0 0" />
      <geometry>
        <mesh filename="package://dyros_jet_description/meshes/base_link.stl" />
      </geometry>
      <material
        name="">
        <color rgba="0.59216 0.61961 0.65098 1" />
      </material>
    </visual>
    <collision>
      <origin
        xyz="0 0 0"
        rpy="0 0 0" />
      <geometry>
        <mesh
          filename="package://dyros_jet_description/meshes/base_link.stl" />
      </geometry>	
    </collision>
  </link>
  <link name="L_HipYaw_Link">
    <inertial>
      <origin
        xyz="-0.030891 -0.00026292 -0.066857"
        rpy="0 0 0" />
      <mass value="1.495" />
      <inertia
        ixx="0.009929"
        ixy="1.2E-05"
        ixz="0.003862"
        iyy="0.013976"
        iyz="2.6E-05"
        izz="0.00478" />
    </inertial>name (required)
    Specifies a unique name of the joint
    <visual>
      <origin
        xyz="0 0 0"
        rpy="0 0 0" />
      <geometry>
        <mesh
          filename="package://dyros_jet_description/meshes/L_HipYaw_Link.stl" />
      </geometry>
      <material
        name="">
        <color
          rgba="0.59216 0.61961 0.65098 1" />
      </material>
    </visual>
    <collision>
      <origin
        xyz="0 0 0"
        rpy="0 0 0" />
      <geometry>
        <mesh
          filename="package://dyros_jet_description/meshes/L_HipYaw_Link.stl" />
      </geometry>
    </collision>
  </link>
  <joint
    name="L_HipYaw"
    type="revolute">
    <origin
      xyz="0 0.10526 0"
      rpy="0 0 0" />
    <parent
      link="base_link" />
    <child
      link="L_HipYaw_Link" />
    <axis
      xyz="0 0 -1" />
    <limit
      effort="30"
      velocity="1" lower="-3.14" upper="3.14" />
  </joint>
  <link
    name="L_HipRoll_Link">
    <inertial>
      <origin
        xyz="0 -0.010643 0.00033181"
        rpy="0 0 0" />
      <mass
        value="1.023" />
      <inertia
        ixx="0.00179"
        ixy="0"
        ixz="0"
        iyy="0.000627"
        iyz="0"
        izz="0.001839" />
    </inertial>
    <visual>
      <origin
        xyz="0 0 0"
        rpy="0 0 0" />
      <geometry>
        <mesh
          filename="package://dyros_jet_description/meshes/L_HipRoll_Link.stl" />
      </geometry>
      <material
        name="">
        <color
          rgba="0.59216 0.61961 0.65098 1" />
      </material>
    </visual>
    <collision>
      <origin
        xyz="0 0 0"
        rpy="0 0 0" />
      <geometry>
        <mesh
          filename="package://dyros_jet_description/meshes/L_HipRoll_Link.stl" />
      </geometry>
    </collision>
  </link>
  <joint
    name="L_HipRoll"
    type="revolute">
    <origin
      xyz="-0.0059 -0.00026292 -0.1349"
      rpy="0 0 0" />
    <parent
      link="L_HipYaw_Link" />
    <child
      link="L_HipRoll_Link" />
    <axis
      xyz="1 0 0" />
    <limit
      effort="30"
      velocity="1" lower="-3.14" upper="3.14" />
  </joint>
  <link
    name="L_HipPitch_Link">
    <inertial>
      <origin
        xyz="0.12623 -0.012 -0.24119"
        rpy="0 0 0" />
      <mass
        value="3.2021" />
      <inertia
        ixx="0.219278"
        ixy="-0.00485"
        ixz="-0.108243"
        iyy="0.271379"
        iyz="0.009268"
        izz="0.066664" />
    </inertial>
    <visual>
      <origin
        xyz="0 0 0"
        rpy="0 0 0" />
      <geometry>
        <mesh
          filename="package://dyros_jet_description/meshes/L_HipPitch_Link.stl" />
      </geometry>
      <material
        name="">
        <color
          rgba="0.59216 0.61961 0.65098 1" />
      </material>
    </visual>
    <collision>
      <origin
        xyz="0 0 0"
        rpy="0 0 0" />
      <geometry>
        <mesh
          filename="package://dyros_jet_description/meshes/L_HipPitch_Link.stl" />
      </geometry>
    </collision>
  </link>
  <joint
    name="L_HipPitch"
    type="revolute">
    <origin
      xyz="0 0 0"
      rpy="0 0 0" />
    <parent
      link="L_HipRoll_Link" />
    <child
      link="L_HipPitch_Link" />
    <axis
      xyz="0 1 0" />
    <limit
      effort="30"
      velocity="1" lower="-3.14" upper="3.14" />
  </joint>
  <link
    name="L_KneePitch_Link">
    <inertial>
      <origin
        xyz="0.057127 -0.015978 -0.23954"
        rpy="0 0 0" />
      <mass
        value="2.0241" />
      <inertia
        ixx="0.14376"
        ixy="-0.001933"
        ixz="-0.028862"
        iyy="0.146408"
        iyz="0.010406"
        izz="0.012166" />
    </inertial>
    <visual>
      <origin
        xyz="0 0 0"
        rpy="0 0 0" />
      <geometry>
        <mesh
          filename="package://dyros_jet_description/meshes/L_KneePitch_Link.stl" />
      </geometry>
      <material
        name="">
        <color
          rgba="0.59216 0.61961 0.65098 1" />
      </material>
    </visual>
    <collision>
      <origin
        xyz="0 0 0"
        rpy="0 0 0" />
      <geometry>
        <mesh
          filename="package://dyros_jet_description/meshes/L_KneePitch_Link.stl" />
      </geometry>
    </collision>
  </link>
  <joint
    name="L_KneePitch"
    type="revolute">
    <origin
      xyz="0.1515 -0.01075 -0.33906"
      rpy="0 0 0" />
    <parent
      link="L_HipPitch_Link" />
    <child
      link="L_KneePitch_Link" />
    <axis
      xyz="0 1 0" />
    <limit
      effort="30"
      velocity="1" lower="-3.14" upper="3.14" />
  </joint>
  <link
    name="L_AnklePitch_Link">
    <inertial>
      <origin
        xyz="-0.01052 0 0"
        rpy="0 0 0" />
      <mass
        value="1.0349" />
      <inertia
        ixx="0.000637"
        ixy="0"
        ixz="0"
        iyy="0.001803"
        iyz="0"
        izz="0.001843" />
    </inertial>
    <visual>
      <origin
        xyz="0 0 0"
        rpy="0 0 0" />
      <geometry>
        <mesh
          filename="package://dyros_jet_description/meshes/L_AnklePitch_Link.stl" />
      </geometry>
      <material
        name="">
        <color
          rgba="0.59216 0.61961 0.65098 1" />
      </material>
    </visual>
    <collision>
      <origin
        xyz="0 0 0"
        rpy="0 0 0" />
      <geometry>
        <mesh
          filename="package://dyros_jet_description/meshes/L_AnklePitch_Link.stl" />
      </geometry>
    </collision>
  </link>
  <joint
    name="L_AnklePitch"
    type="revolute">
    <origin
      xyz="0.06 0.00485 -0.36794"
      rpy="0 0 0" />
    <parent
      link="L_KneePitch_Link" />
    <child
      link="L_AnklePitch_Link" />
    <axis
      xyz="0 1 0" />
    <limit
      effort="30"
      velocity="1" lower="-3.14" upper="3.14" />
  </joint>
  <link
    name="L_AnkleRoll_Link">
    <inertial>
      <origin
        xyz="-0.0013994 0 -0.086297"
        rpy="0 0 0" />
      <mass
        value="1.297" />
      <inertia
        ixx="0.012604"
        ixy="0"
        ixz="9.1E-05"
        iyy="0.018122"
        iyz="0"
        izz="0.010758" />
    </inertial>
    <visual>
      <origin
        xyz="0 0 0"
        rpy="0 0 0" />
      <geometry>
        <mesh
          filename="package://dyros_jet_description/meshes/L_AnkleRoll_Link.stl" />
      </geometry>
      <material
        name="">
        <color
          rgba="0.59216 0.61961 0.65098 1" />
      </material>
    </visual>
    <collision>
      <origin
        xyz="0 0 0"
        rpy="0 0 0" />
      <geometry>
        <mesh
          filename="package://dyros_jet_description/meshes/L_AnkleRoll_Link.stl" />
      </geometry>
    </collision>
  </link>
  <joint
    name="L_AnkleRoll"
    type="revolute">
    <origin
      xyz="0 0 0"
      rpy="0 0 0" />
    <parent
      link="L_AnklePitch_Link" />
    <child
      link="L_AnkleRoll_Link" />
    <axis
      xyz="1 0 0" />
    <limit
      effort="30"
      velocity="1" lower="-3.14" upper="3.14" />
  </joint>
  <link
    name="R_HipYaw_Link">
    <inertial>
      <origin
        xyz="-0.030891 0 -0.066857"
        rpy="0 0 0" />
      <mass
        value="1.495" />
      <inertia
        ixx="0.009929"
        ixy="0"
        ixz="0.003862"
        iyy="0.013976"
        iyz="0"
        izz="0.00478" />
    </inertial>
    <visual>
      <origin
        xyz="0 0 0"
        rpy="0 0 0" />
      <geometry>
        <mesh
          filename="package://dyros_jet_description/meshes/R_HipYaw_Link.stl" />
      </geometry>
      <material
        name="">
        <color
          rgba="0.59216 0.61961 0.65098 1" />
      </material>
    </visual>
    <collision>
      <origin
        xyz="0 0 0"
        rpy="0 0 0" />
      <geometry>
        <mesh
          filename="package://dyros_jet_description/meshes/R_HipYaw_Link.stl" />
      </geometry>
    </collision>
  </link>
  <joint
    name="R_HipYaw"
    type="revolute">
    <origin
      xyz="0 -0.105 0"
      rpy="0 0 0" />
    <parent
      link="base_link" />
    <child
      link="R_HipYaw_Link" />
    <axis
      xyz="0 0 -1" />
    <limit
      effort="30"
      velocity="1" lower="-3.14" upper="3.14" />
  </joint>
  <link
    name="R_HipRoll_Link">
    <inertial>
      <origin
        xyz="0 0.010643 0.00033181"
        rpy="0 0 0" />
      <mass
        value="1.023" />
      <inertia
        ixx="0.00179"
        ixy="0"
        ixz="0"
        iyy="0.000627"
        iyz="0"
        izz="0.001839" />
    </inertial>
    <visual>
      <origin
        xyz="0 0 0"
        rpy="0 0 0" />
      <geometry>
        <mesh
          filename="package://dyros_jet_description/meshes/R_HipRoll_Link.stl" />
      </geometry>
      <material
        name="">
        <color
          rgba="0.59216 0.61961 0.65098 1" />
      </material>
    </visual>
    <collision>
      <origin
        xyz="0 0 0"
        rpy="0 0 0" />
      <geometry>
        <mesh
          filename="package://dyros_jet_description/meshes/R_HipRoll_Link.stl" />
      </geometry>
    </collision>
  </link>
  <joint
    name="R_HipRoll"
    type="revolute">
    <origin
      xyz="-0.0059 0 -0.1349"
      rpy="-0.018707 -6.6457E-18 -5.7725E-16" />
    <parent
      link="R_HipYaw_Link" />
    <child
      link="R_HipRoll_Link" />
    <axis
      xyz="1 0 0" />
    <limit
      effort="30"
      velocity="1" lower="-3.14" upper="3.14" />
  </joint>
  <link
    name="R_HipPitch_Link">
    <inertial>
      <origin
        xyz="0.12623 0.012 -0.24119"
        rpy="0 0 0" />
      <mass
        value="3.2021" />
      <inertia
        ixx="0.219278"
        ixy="0.00485"
        ixz="-0.108243"
        iyy="0.271379"
        iyz="-0.009268"
        izz="0.066664" />
    </inertial>
    <visual>
      <origin
        xyz="0 0 0"
        rpy="0 0 0" />
      <geometry>
        <mesh
          filename="package://dyros_jet_description/meshes/R_HipPitch_Link.stl" />
      </geometry>
      <material
        name="">
        <color
          rgba="0.59216 0.61961 0.65098 1" />
      </material>
    </visual>
    <collision>
      <origin
        xyz="0 0 0"
        rpy="0 0 0" />
      <geometry>
        <mesh
          filename="package://dyros_jet_description/meshes/R_HipPitch_Link.stl" />
      </geometry>
    </collision>
  </link>
  <joint
    name="R_HipPitch"
    type="revolute">
    <origin
      xyz="0 0 0"
      rpy="3.4694E-18 7.7037E-34 -3.6352E-33" />
    <parent
      link="R_HipRoll_Link" />
    <child
      link="R_HipPitch_Link" />
    <axis
      xyz="0 -1 0" />
    <limit
      effort="30"
      velocity="1" lower="-3.14" upper="3.14" />
  </joint>
  <link
    name="R_KneePitch_Link">
    <inertial>
      <origin
        xyz="0.057127 0.015978 -0.2396"
        rpy="0 0 0" />
      <mass
        value="2.0241" />
      <inertia
        ixx="0.143814"
        ixy="0.001933"
        ixz="-0.028868"
        iyy="0.146462"
        iyz="-0.010408"
        izz="0.012166" />
    </inertial>
    <visual>
      <origin
        xyz="0 0 0"
        rpy="0 0 0" />
      <geometry>
        <mesh
          filename="package://dyros_jet_description/meshes/R_KneePitch_Link.stl" />
      </geometry>
      <material
        name="">
        <color
          rgba="0.59216 0.61961 0.65098 1" />
      </material>
    </visual>
    <collision>
      <origin
        xyz="0 0 0"
        rpy="0 0 0" />
      <geometry>
        <mesh
          filename="package://dyros_jet_description/meshes/R_KneePitch_Link.stl" />
      </geometry>
    </collision>
  </link>
  <joint
    name="R_KneePitch"
    type="revolute">
    <origin
      xyz="0.1515 0.01075 -0.339"
      rpy="-1.7347E-17 3.0195E-18 5.7728E-16" />
    <parent
      link="R_HipPitch_Link" />
    <child
      link="R_KneePitch_Link" />
    <axis
      xyz="0 -1 0" />
    <limit
      effort="30"
      velocity="1" lower="-3.14" upper="3.14" />
  </joint>
  <link
    name="R_AnklePitch_Link">
    <inertial>
      <origin
        xyz="-0.01052 0 0"
        rpy="0 0 0" />
      <mass
        value="1.0349" />
      <inertia
        ixx="0.000637"
        ixy="0"
        ixz="0"
        iyy="0.001803"
        iyz="0"
        izz="0.001843" />
    </inertial>
    <visual>
      <origin
        xyz="0 0 0"
        rpy="0 0 0" />
      <geometry>
        <mesh
          filename="package://dyros_jet_description/meshes/R_AnklePitch_Link.stl" />
      </geometry>
      <material
        name="">
        <color
          rgba="0.59216 0.61961 0.65098 1" />
      </material>
    </visual>
    <collision>
      <origin
        xyz="0 0 0"
        rpy="0 0 0" />
      <geometry>
        <mesh
          filename="package://dyros_jet_description/meshes/R_AnklePitch_Link.stl" />
      </geometry>
    </collision>
  </link>
  <joint
    name="R_AnklePitch"
    type="revolute">
    <origin
      xyz="0.06 -0.00485 -0.368"
      rpy="-1.2837E-16 -4.4988E-16 -3.5523E-16" />
    <parent
      link="R_KneePitch_Link" />
    <child
      link="R_AnklePitch_Link" />
    <axis
      xyz="0 -1 0" />
    <limit
      effort="30"
      velocity="1" lower="-3.14" upper="3.14" />
  </joint>
  <link
    name="R_AnkleRoll_Link">
    <inertial>
      <origin
        xyz="-0.0013994 0.0016143 -0.086282"
        rpy="0 0 0" />
      <mass
        value="1.297" />
      <inertia
        ixx="0.012604"
        ixy="-2E-06"
        ixz="9.1E-05"
        iyy="0.018119"
        iyz="-0.000138"
        izz="0.01076" />
    </inertial>
    <visual>
      <origin
        xyz="0 0 0"
        rpy="0 0 0" />
      <geometry>
        <mesh
          filename="package://dyros_jet_description/meshes/R_AnkleRoll_Link.stl" />
      </geometry>
      <material
        name="">
        <color
          rgba="0.59216 0.61961 0.65098 1" />
      </material>
    </visual>
    <collision>
      <origin
        xyz="0 0 0"
        rpy="0 0 0" />
      <geometry>
        <mesh
          filename="package://dyros_jet_description/meshes/R_AnkleRoll_Link.stl" />
      </geometry>
    </collision>
  </link>
  <joint
    name="R_AnkleRoll"
    type="revolute">
    <origin
      xyz="0 0 0"
      rpy="0 9.8608E-32 1.8489E-32" />
    <parent
      link="R_AnklePitch_Link" />
    <child
      link="R_AnkleRoll_Link" />
    <axis
      xyz="1 0 0" />
    <limit
      effort="30"
      velocity="1" lower="-3.14" upper="3.14" />
  </joint>
  <link
    name="WaistPitch_Link">
    <inertial>
      <origin
        xyz="-1.1233E-16 -5.6053E-18 0.14577"
        rpy="0 0 0" />
      <mass
        value="0.17684" />
      <inertia
        ixx="0.003844"
        ixy="0"
        ixz="0"
        iyy="0.004215"
        iyz="0"
        izz="0.000457" />
    </inertial>
    <visual>
      <origin
        xyz="0 0 0"
        rpy="0 0 0" />
      <geometry>
        <mesh
          filename="package://dyros_jet_description/meshes/WaistPitch_Link.stl" />
      </geometry>
      <material
        name="">
        <color
          rgba="0.59216 0.61961 0.65098 1" />
      </material>
    </visual>
    <collision>
      <origin
        xyz="0 0 0"
        rpy="0 0 0" />
      <geometry>
        <mesh
          filename="package://dyros_jet_description/meshes/WaistPitch_Link.stl" />
      </geometry>
    </collision>
  </link>
  <joint
    name="WaistPitch"
    type="revolute">
    <origin
      xyz="0 0 0"
      rpy="0 0 0" />
    <parent
      link="base_link" />
    <child
      link="WaistPitch_Link" />
    <axis
      xyz="0 0 1" />
    <limit
      effort="30"
      velocity="1" lower="-3.14" upper="3.14" />
  </joint>
  <link
    name="WaistYaw_Link">
    <inertial>
      <origin
        xyz="-8E-06 0 0.121"
        rpy="0 0 0" />
      <mass
        value="10.78" />
      <inertia
        ixx="0.262766"
        ixy="0"
        ixz="0"
        iyy="0.242504"
        iyz="0"
        izz="0.109346" />
    </inertial>
    <visual>
      <origin
        xyz="0 0 0"
        rpy="0 0 0" />
      <geometry>
        <mesh
          filename="package://dyros_jet_description/meshes/WaistYaw_Link.stl" />
      </geometry>
      <material
        name="">
        <color
          rgba="0.59216 0.61961 0.65098 1" />
      </material>
    </visual>
    <collision>
      <origin
        xyz="0 0 0"
        rpy="0 0 0" />
      <geometry>
        <mesh
          filename="package://dyros_jet_description/meshes/WaistYaw_Link.stl" />
      </geometry>
    </collision>
  </link>
  <joint
    name="WaistYaw"
    type="revolute">
    <origin
      xyz="0 0 0.186"
      rpy="0 0 0" />
    <parent
      link="WaistPitch_Link" />
    <child
      link="WaistYaw_Link" />
    <axis
      xyz="-1 0 0" />
    <limit
      effort="30"
      velocity="1" lower="-3.14" upper="3.14" />
  </joint>
  <link
    name="L_ShoulderPitch_Link">
    <inertial>
      <origin
        xyz="0.00028444 -0.0013968 0"
        rpy="0 0 0" />
      <mass
        value="0.92826" />
      <inertia
        ixx="0.000473"
        ixy="0"
        ixz="0"
        iyy="0.0015422"
        iyz="0"
        izz="0.00156" />
    </inertial>
    <visual>
      <origin
        xyz="0 0 0"
        rpy="0 0 0" />
      <geometry>
        <mesh
          filename="package://dyros_jet_description/meshes/L_ShoulderPitch_Link.stl" />
      </geometry>
      <material
        name="">
        <color
          rgba="0.59216 0.61961 0.65098 1" />
      </material>
    </visual>
    <collision>
      <origin
        xyz="0 0 0"
        rpy="0 0 0" />
      <geometry>
        <mesh
          filename="package://dyros_jet_description/meshes/L_ShoulderPitch_Link.stl" />
      </geometry>
    </collision>
  </link>
  <joint
    name="L_ShoulderPitch"
    type="revolute">
    <origin
      xyz="0 0.17 0.239"
      rpy="0.5236 0 -4.6787E-15" />
    <parent
      link="WaistYaw_Link" />
    <child
      link="L_ShoulderPitch_Link" />
    <axis
      xyz="0 1 0" />
    <limit
      effort="30"
      velocity="1" lower="-3.14" upper="3.14" />
  </joint>
  <link
    name="L_ShoulderRoll_Link">
    <inertial>
      <origin
        xyz="0 0.030402 0.033562"
        rpy="0 0 0" />
      <mass
        value="0.37361" />
      <inertia
        ixx="0.001421"
        ixy="0"
        ixz="0"
        iyy="0.001585"
        iyz="0.000389"
        izz="0.001839" />
    </inertial>
    <visual>
      <origin
        xyz="0 0 0"
        rpy="0 0 0" />
      <geometry>
        <mesh
          filename="package://dyros_jet_description/meshes/L_ShoulderRoll_Link.stl" />
      </geometry>
      <material
        name="">
        <color
          rgba="0.59216 0.61961 0.65098 1" />
      </material>
    </visual>
    <collision>
      <origin
        xyz="0 0 0"
        rpy="0 0 0" />
      <geometry>
        <mesh
          filename="package://dyros_jet_description/meshes/L_ShoulderRoll_Link.stl" />
      </geometry>
    </collision>
  </link>
  <joint
    name="L_ShoulderRoll"
    type="revolute">
    <origin
      xyz="0 0 0"
      rpy="0 0 -7.8886E-31" />
    <parent
      link="L_ShoulderPitch_Link" />
    <child
      link="L_ShoulderRoll_Link" />
    <axis
      xyz="1 0 0" />
    <limit
      effort="30"
      velocity="1" lower="-3.14" upper="3.14" />
  </joint>
  <link
    name="L_ShoulderYaw_Link">
    <inertial>
      <origin
        xyz="-0.00046649 0.21409 0"
        rpy="0 0 0" />
      <mass
        value="1.7512" />
      <inertia
        ixx="0.090419"
        ixy="-0.00024"
        ixz="0"
        iyy="0.00126"
        iyz="0"
        izz="0.090836" />
    </inertial>
    <visual>
      <origin
        xyz="0 0 0"
        rpy="0 0 0" />
      <geometry>
        <mesh
          filename="package://dyros_jet_description/meshes/L_ShoulderYaw_Link.stl" />
      </geometry>
      <material
        name="">
        <color
          rgba="0.59216 0.61961 0.65098 1" />
      </material>
    </visual>
    <collision>
      <origin
        xyz="0 0 0"
        rpy="0 0 0" />
      <geometry>
        <mesh
          filename="package://dyros_jet_description/meshes/L_ShoulderYaw_Link.stl" />
      </geometry>
    </collision>
  </link>
  <joint
    name="L_ShoulderYaw"
    type="revolute">
    <origin
      xyz="0 0 0.028856"
      rpy="1.6653E-15 2.6672E-15 -1.1833E-29" />
    <parent
      link="L_ShoulderRoll_Link" />
    <child
      link="L_ShoulderYaw_Link" />
    <axis
      xyz="0 1 0" />
    <limit
      effort="30"
      velocity="1" lower="-3.14" upper="3.14" />
  </joint>
  <link
    name="L_ElbowRoll_Link">
    <inertial>
      <origin
        xyz="-0.00013156 0.027019 0.070625"
        rpy="0 0 0" />
      <mass
        value="0.83343" />
      <inertia
        ixx="0.00592"
        ixy="-3E-06"
        ixz="-8E-06"
        iyy="0.004878"
        iyz="0.001689"
        izz="0.001797" />
    </inertial>
    <visual>
      <origin
        xyz="0 0 0"
        rpy="0 0 0" />
      <geometry>
        <mesh
          filename="package://dyros_jet_description/meshes/L_ElbowRoll_Link.stl" />
      </geometry>
      <material
        name="">
        <color
          rgba="0.59216 0.61961 0.65098 1" />
      </material>
    </visual>
    <collision>
      <origin
        xyz="0 0 0"
        rpy="0 0 0" />
      <geometry>
        <mesh
          filename="package://dyros_jet_description/meshes/L_ElbowRoll_Link.stl" />
      </geometry>
    </collision>
  </link>
  <joint
    name="L_ElbowRoll"
    type="revolute">
    <origin
      xyz="0 0.294 0"
      rpy="-5.2736E-15 2.2506E-15 4.0518E-15" />
    <parent
      link="L_ShoulderYaw_Link" />
    <child
      link="L_ElbowRoll_Link" />
    <axis
      xyz="1 0 0" />
    <limit
      effort="30"
      velocity="1" lower="-3.14" upper="3.14" />
  </joint>
  <link
    name="L_WristYaw_Link">
    <inertial>
      <origin
        xyz="-0.00052833 0.21354 0"
        rpy="0 0 0" />
      <mass
        value="0.52387" />
      <inertia
        ixx="0.026688"
        ixy="-7.8E-05"
        ixz="0"
        iyy="0.000269"
        iyz="0"
        izz="0.026765" />
    </inertial>
    <visual>
      <origin
        xyz="0 0 0"
        rpy="0 0 0" />
      <geometry>
        <mesh
          filename="package://dyros_jet_description/meshes/L_WristYaw_Link.stl" />
      </geometry>
      <material
        name="">
        <color
          rgba="0.59216 0.61961 0.65098 1" />
      </material>
    </visual>
    <collision>
      <origin
        xyz="0 0 0"
        rpy="0 0 0" />
      <geometry>
        <mesh
          filename="package://dyros_jet_description/meshes/L_WristYaw_Link.stl" />
      </geometry>
    </collision>
  </link>
  <joint
    name="L_WristYaw"
    type="revolute">
    <origin
      xyz="0 0 0.075"
      rpy="-5.5511E-17 0 0" />
    <parent
      link="L_ElbowRoll_Link" />
    <child
      link="L_WristYaw_Link" />
    <axis
      xyz="0 1 0" />
    <limit
      effort="30"
      velocity="1" lower="-3.14" upper="3.14" />
  </joint>
  <link
    name="L_WristRoll_Link">
    <inertial>
      <origin
        xyz="0 0.029698 0"
        rpy="0 0 0" />
      <mass
        value="0.0695" />
      <inertia
        ixx="8.3E-05"
        ixy="0"
        ixz="0"
        iyy="9.0005E-05"
        iyz="0"
        izz="0.000153" />
    </inertial>
    <visual>
      <origin
        xyz="0 0 0"
        rpy="0 0 0" />
      <geometry>
        <mesh
          filename="package://dyros_jet_description/meshes/L_WristRoll_Link.stl" />
      </geometry>
      <material
        name="">
        <color
          rgba="0.59216 0.61961 0.65098 1" />
      </material>
    </visual>
    <collision>
      <origin
        xyz="0 0 0"
        rpy="0 0 0" />
      <geometry>
        <mesh
          filename="package://dyros_jet_description/meshes/L_WristRoll_Link.stl" />
      </geometry>
    </collision>
  </link>
  <joint
    name="L_WristRoll"
    type="revolute">
    <origin
      xyz="-0.00015 0.3085 0"
      rpy="3.7192E-15 -2.0473E-15 -4.2369E-15" />
    <parent
      link="L_WristYaw_Link" />
    <child
      link="L_WristRoll_Link" />
    <axis
      xyz="1 0 0" />
    <limit
      effort="30"
      velocity="1" lower="-3.14" upper="3.14" />
  </joint>
  <link
    name="L_HandYaw_Link">
    <inertial>
      <origin
        xyz="0 0.20231 0.0031654"
        rpy="0 0 0" />
      <mass
        value="1.206" />
      <inertia
        ixx="0.05396"
        ixy="0"
        ixz="0"
        iyy="0.002601"
        iyz="0.00084"
        izz="0.055766" />
    </inertial>
    <visual>
      <origin
        xyz="0 0 0"
        rpy="0 0 0" />
      <geometry>
        <mesh
          filename="package://dyros_jet_description/meshes/L_HandYaw_Link.stl" />
      </geometry>
      <material
        name="">
        <color
          rgba="0.59216 0.61961 0.65098 1" />
      </material>
    </visual>
    <collision>
      <origin
        xyz="0 0 0"
        rpy="0 0 0" />
      <geometry>
        <mesh
          filename="package://dyros_jet_description/meshes/L_HandYaw_Link.stl" />
      </geometry>
    </collision>
  </link>
  <joint
    name="L_HandYaw"
    type="revolute">
    <origin
      xyz="0 0 0"
      rpy="5.5511E-17 0 -3.9443E-31" />
    <parent
      link="L_WristRoll_Link" />
    <child
      link="L_HandYaw_Link" />
    <axis
      xyz="0 1 0" />
    <limit
      effort="30"
      velocity="1" lower="-3.14" upper="3.14" />
  </joint>

  <link
    name="R_ShoulderPitch_Link">
    <inertial>
      <origin
        xyz="0.00028444 0.0013968 0"
        rpy="0 0 0" />
      <mass
        value="0.92826" />
      <inertia
        ixx="0.000473"
        ixy="0"
        ixz="0"
        iyy="0.0015422"
        iyz="0"
        izz="0.00156" />
    </inertial>
    <visual>
      <origin
        xyz="0 0 0"
        rpy="0 0 0" />
      <geometry>
        <mesh
          filename="package://dyros_jet_description/meshes/R_ShoulderPitch_Link.stl" />
      </geometry>
      <material
        name="">
        <color
          rgba="0.59216 0.61961 0.65098 1" />
      </material>
    </visual>
    <collision>
      <origin
        xyz="0 0 0"
        rpy="0 0 0" />
      <geometry>
        <mesh
          filename="package://dyros_jet_description/meshes/R_ShoulderPitch_Link.stl" />
      </geometry>
    </collision>
  </link>
  <joint
    name="R_ShoulderPitch"
    type="revolute">
    <origin
      xyz="0 -0.17 0.239"
      rpy="-0.5236 1.6324E-15 3.0939E-15" />
    <parent
      link="WaistYaw_Link" />
    <child
      link="R_ShoulderPitch_Link" />
    <axis
      xyz="0 -1 0" />
    <limit
      effort="30"
      velocity="1" lower="-3.14" upper="3.14" />
  </joint>
  <link
    name="R_ShoulderRoll_Link">
    <inertial>
      <origin
        xyz="0 -0.030402 0.033562"
        rpy="0 0 0" />
      <mass
        value="0.37361" />
      <inertia
        ixx="0.001421"
        ixy="0"
        ixz="0"
        iyy="0.001585"
        iyz="-0.000389"
        izz="0.001839" />
    </inertial>
    <visual>
      <origin
        xyz="0 0 0"
        rpy="0 0 0" />
      <geometry>
        <mesh
          filename="package://dyros_jet_description/meshes/R_ShoulderRoll_Link.stl" />
      </geometry>
      <material
        name="">
        <color
          rgba="0.59216 0.61961 0.65098 1" />
      </material>
    </visual>
    <collision>
      <origin
        xyz="0 0 0"
        rpy="0 0 0" />
      <geometry>
        <mesh
          filename="package://dyros_jet_description/meshes/R_ShoulderRoll_Link.stl" />
      </geometry>
    </collision>
  </link>
  <joint
    name="R_ShoulderRoll"
    type="revolute">
    <origin
      xyz="0 0 0"
      rpy="0 0 -1.9722E-31" />
    <parent
      link="R_ShoulderPitch_Link" />
    <child
      link="R_ShoulderRoll_Link" />
    <axis
      xyz="1 0 0" />
    <limit
      effort="30"
      velocity="1" lower="-3.14" upper="3.14" />
  </joint>
  <link
    name="R_ShoulderYaw_Link">
    <inertial>
      <origin
        xyz="-0.00046649 -0.21409 0"
        rpy="0 0 0" />
      <mass
        value="1.7512" />
      <inertia
        ixx="0.090419"
        ixy="0.00024"
        ixz="0"
        iyy="0.00126"
        iyz="0"
        izz="0.090836" />
    </inertial>
    <visual>
      <origin
        xyz="0 0 0"
        rpy="0 0 0" />
      <geometry>
        <mesh
          filename="package://dyros_jet_description/meshes/R_ShoulderYaw_Link.stl" />
      </geometry>
      <material
        name="">
        <color
          rgba="0.59216 0.61961 0.65098 1" />
      </material>
    </visual>
    <collision>
      <origin
        xyz="0 0 0"
        rpy="0 0 0" />
      <geometry>
        <mesh
          filename="package://dyros_jet_description/meshes/R_ShoulderYaw_Link.stl" />
      </geometry>
    </collision>
  </link>
  <joint
    name="R_ShoulderYaw"
    type="revolute">
    <origin
      xyz="0 0 0.028856"
      rpy="3.3862E-15 1.3323E-16 -6.4991E-15" />
    <parent
      link="R_ShoulderRoll_Link" />
    <child
      link="R_ShoulderYaw_Link" />
    <axis
      xyz="0 -1 0" />
    <limit
      effort="30"
      velocity="1" lower="-3.14" upper="3.14" />
  </joint>
  <link
    name="R_ElbowRoll_Link">
    <inertial>
      <origin
        xyz="-0.00013156 -0.027019 0.070625"
        rpy="0 0 0" />
      <mass
        value="0.83343" />
      <inertia
        ixx="0.00592"
        ixy="3E-06"
        ixz="-8E-06"
        iyy="0.004878"
        iyz="-0.001689"
        izz="0.001797" />
    </inertial>
    <visual>
      <origin
        xyz="0 0 0"
        rpy="0 0 0" />
      <geometry>
        <mesh
          filename="package://dyros_jet_description/meshes/R_ElbowRoll_Link.stl" />
      </geometry>
      <material
        name="">
        <color
          rgba="0.59216 0.61961 0.65098 1" />
      </material>
    </visual>
    <collision>
      <origin
        xyz="0 0 0"
        rpy="0 0 0" />
      <geometry>
        <mesh
          filename="package://dyros_jet_description/meshes/R_ElbowRoll_Link.stl" />
      </geometry>
    </collision>
  </link>
  <joint
    name="R_ElbowRoll"
    type="revolute">
    <origin
      xyz="0 -0.294 0"
      rpy="8.7708E-15 6.5224E-15 6.7691E-15" />
    <parent
      link="R_ShoulderYaw_Link" />
    <child
      link="R_ElbowRoll_Link" />
    <axis
      xyz="1 0 0" />
    <limit
      effort="30"
      velocity="1" lower="-3.14" upper="3.14" />
  </joint>
  <link
    name="R_WristYaw_Link">
    <inertial>
      <origin
        xyz="-0.00052833 -0.21354 0"
        rpy="0 0 0" />
      <mass
        value="0.52387" />
      <inertia
        ixx="0.026688"
        ixy="7.8E-05"
        ixz="0"
        iyy="0.000269"
        iyz="0"
        izz="0.026765" />
    </inertial>
    <visual>
      <origin
        xyz="0 0 0"
        rpy="0 0 0" />
      <geometry>
        <mesh
          filename="package://dyros_jet_description/meshes/R_WristYaw_Link.stl" />
      </geometry>
      <material
        name="">
        <color
          rgba="0.59216 0.61961 0.65098 1" />
      </material>
    </visual>
    <collision>
      <origin
        xyz="0 0 0"
        rpy="0 0 0" />
      <geometry>
        <mesh
          filename="package://dyros_jet_description/meshes/R_WristYaw_Link.stl" />
      </geometry>
    </collision>
  </link>
  <joint
    name="R_WristYaw"
    type="revolute">
    <origin
      xyz="0 0 0.075"
      rpy="5.5511E-17 7.8886E-31 -3.7657E-15" />
    <parent
      link="R_ElbowRoll_Link" />
    <child
      link="R_WristYaw_Link" />
    <axis
      xyz="0 -1 0" />
    <limit
      effort="30"
      velocity="1" lower="-3.14" upper="3.14" />
  </joint>
  <link
    name="R_WristRoll_Link">
    <inertial>
      <origin
        xyz="0 -0.029698 0"
        rpy="0 0 0" />
      <mass
        value="0.0695" />
      <inertia
        ixx="8.3E-05"
        ixy="0"
        ixz="0"
        iyy="9E-05"
        iyz="0"
        izz="0.000153" />
    </inertial>
    <visual>
      <origin
        xyz="0 0 0"
        rpy="0 0 0" />
      <geometry>
        <mesh
          filename="package://dyros_jet_description/meshes/R_WristRoll_Link.stl" />
      </geometry>
      <material
        name="">
        <color
          rgba="0.59216 0.61961 0.65098 1" />
      </material>
    </visual>
    <collision>
      <origin
        xyz="0 0 0"
        rpy="0 0 0" />
      <geometry>
        <mesh
          filename="package://dyros_jet_description/meshes/R_WristRoll_Link.stl" />
      </geometry>
    </collision>
  </link>
  <joint
    name="R_WristRoll"
    type="revolute">
    <origin
      xyz="-0.00015 -0.3085 0"
      rpy="-3.1641E-15 -4.6105E-15 -2.8519E-15" />
    <parent
      link="R_WristYaw_Link" />
    <child
      link="R_WristRoll_Link" />
    <axis
      xyz="1 0 0" />
    <limit
      effort="30"
      velocity="1" lower="-3.14" upper="3.14" />
  </joint>
  <link
    name="R_HandYaw_Link">
    <inertial>
      <origin
        xyz="0 -0.20231 -0.0031654"
        rpy="0 0 0" />
      <mass
        value="1.206" />
      <inertia
        ixx="0.05396"
        ixy="0"
        ixz="0"
        iyy="0.002601"
        iyz="0.00084"
        izz="0.055766" />
    </inertial>
    <visual>
      <origin
        xyz="0 0 0"
        rpy="0 0 0" />
      <geometry>
        <mesh
          filename="package://dyros_jet_description/meshes/R_HandYaw_Link.stl" />
      </geometry>
      <material
        name="">
        <color
          rgba="0.59216 0.61961 0.65098 1" />
      </material>
    </visual>
    <collision>
      <origin
        xyz="0 0 0"
        rpy="0 0 0" />
      <geometry>
        <mesh
          filename="package://dyros_jet_description/meshes/R_HandYaw_Link.stl" />
      </geometry>
    </collision>
  </link>
  <joint
    name="R_HandYaw"
    type="revolute">
    <origin
      xyz="0 0 0"
      rpy="0 -1.7256E-31 3.4513E-31" />
    <parent
      link="R_WristRoll_Link" />
    <child
      link="R_HandYaw_Link" />
    <axis
      xyz="0 -1 0" />
    <limit
      effort="30"
      velocity="1" lower="-3.14" upper="3.14" />
  </joint>
</robot>
